Workbook

Sheet Cost_Summary
A3: Cost Summary:
A4: Current Trip Count | B4: =294/30 -> 9.8
A5: Proposed Trip Count | B5: 9.33
A6: Count of DH | B6: 27
A7: Monthly Current Cost (Cr) | B7: 38
A8: Monthly Proposed Fixed Cost (Cr) | B8: 35.88
A9: Adhoc Cost (Cr) | B9: =B8*0.03 -> 1.0764
A10: Total Savings | B10: =-sum(B8:B9)+B7 -> 1.0436

Sheet Accruals Zonal 26th-24th June25

Sheet Location_file
A1: location_name | B1: latitude | C1: longitude | D1: demand | E1: time_window_start (minutes) | F1: time_window_end (minutes) | G1: depot_departure (minutes) | H1: ML | I1: fixed_hop_position | J1: Freq_Allowed
A2: CTL/PBI | B2: 26.104 | C2: 91.523 | D2: 0 | E2: 0 | F2: 5000 | G2: 0 | H2: 32 | I2: NaN | J2: 1
A3: SAT/FKSIL | B3: 24.832 | C3: 92.775 | D3: 877 | E3: 1 | F3: 3240 | G3: 1 | H3: 32 | I3: NaN | J3: 1
A4: SAT/HKD | B4: 24.718 | C4: 92.574 | D4: 241 | E4: 1 | F4: 3240 | G4: 1 | H4: 32 | I4: NaN | J4: 1
A5: SAT/BDPR1 | B5: 24.865 | C5: 92.565 | D5: 278 | E5: 2 | F5: 3240 | G5: 2 | H5: 32 | I5: NaN | J5: 1
A6: SAT/FKKXJ | B6: 24.815 | C6: 92.378 | D6: 455 | E6: 2 | F6: 3240 | G6: 2 | H6: 32 | I6: NaN | J6: 1
A7: SAT/FKSRN | B7: 27.022 | C7: 94.667 | D7: 662.3 | E7: 3 | F7: 3240 | G7: 3 | H7: 32 | I7: NaN | J7: 1
A8: SAT/MNT1 | B8: 27.259 | C8: 94.9109 | D8: 203.5 | E8: 3 | F8: 3240 | G8: 3 | H8: 32 | I8: NaN | J8: 1
A9: SAT/RJH2 | B9: 27.3013 | C9: 95.273 | D9: 347.8 | E9: 3 | F9: 3240 | G9: 3 | H9: 32 | I9: NaN | J9: 1
A10: SAT/BKK1 | B10: 26.486 | C10: 93.978 | D10: 536.5 | E10: 4 | F10: 3240 | G10: 4 | H10: 32 | I10: NaN | J10: 1
A11: SAT/SRU | B11: 26.2833 | C11: 93.8843 | D11: 162.8 | E11: 4 | F11: 3240 | G11: 4 | H11: 32 | I11: NaN | J11: 1
A12: SAT/IMPAL | B12: 24.747 | C12: 93.934 | D12: 484.7 | E12: 5 | F12: 3240 | G12: 5 | H12: 32 | I12: NaN | J12: 1
A13: SAT/FKNHL | B13: 27.161 | C13: 93.679 | D13: 773.3 | E13: 6 | F13: 3240 | G13: 6 | H13: 32 | I13: NaN | J13: 1
... A54: SAT/PALASHBARI | B54: 26.11 | C54: 91.53 | D54: 540.2 | E54: 36 | F54: 3240 | G54: 36 | H54: 32 | I54: NaN | J54: 1

Sheet Expanded_Schedule
A1: Route_ID | B1: Location | C1: Arrival_Time | D1: Departure_Time | E1: Freq | F1: Vehicle_Length | G1: Total_Demand | H1: Route_Sequence
A2: 1 | B2: CTL/PBI | D2: 3020 | E2: 2 | F2: 20 | G2: 1154.4 | H2: CTL/PBI -> SAT/FKMAN -> CTL/PBI
A3: 1 | B3: SAT/FKMAN | C3: 3240 | D3: 3360 | E3: 2 | F3: 20 | G3: 1154.4 | H3: CTL/PBI -> SAT/FKMAN -> CTL/PBI
A4: 1 | B4: CTL/PBI | C4: 3580 | E4: 2 | F4: 20 | G4: 1154.4 | H4: CTL/PBI -> SAT/FKMAN -> CTL/PBI
A5: 2 | B5: CTL/PBI | D5: 2884 | E5: 2 | F5: 14 | G5: 577.2 | H5: CTL/PBI -> SAT/UGR -> CTL/PBI
A6: 2 | B6: SAT/UGR | C6: 3240 | D6: 3360 | E6: 2 | F6: 14 | G6: 577.2 | H6: CTL/PBI -> SAT/UGR -> CTL/PBI
A7: 2 | B7: CTL/PBI | C7: 3716 | E7: 2 | F7: 14 | G7: 577.2 | H7: CTL/PBI -> SAT/UGR -> CTL/PBI
A8: 3 | B8: CTL/PBI | D8: 3225 | E8: 2 | F8: 20 | G8: 1080.4 | H8: CTL/PBI -> SAT/PALASHBARI -> CTL/PBI
A9: 3 | B9: SAT/PALASHBARI | C9: 3240 | D9: 3360 | E9: 2 | F9: 20 | G9: 1080.4 | H9: CTL/PBI -> SAT/PALASHBARI -> CTL/PBI
A10: 3 | B10: CTL/PBI | C10: 3375 | E10: 2 | F10: 20 | G10: 1080.4 | H10: CTL/PBI -> SAT/PALASHBARI -> CTL/PBI
A11: 4 | B11: CTL/PBI | D11: 1180 | E11: 2 | F11: 14 | G11: 547.6 | H11: CTL/PBI -> SAT/PSG -> SAT/MJI1 -> CTL/PBI
A12: 4 | B12: SAT/PSG | C12: 2558 | D12: 2678 | E12: 2 | F12: 14 | G12: 547.6 | H12: CTL/PBI -> SAT/PSG -> SAT/MJI1 -> CTL/PBI
A13: 4 | B13: SAT/MJI1 | C13: 3240 | D13: 3360 | E13: 2 | F13: 14 | G13: 547.6 | H13: CTL/PBI -> SAT/PSG -> SAT/MJI1 -> CTL/PBI
A14: 4 | B14: CTL/PBI | C14: 4344 | E14: 2 | F14: 14 | G14: 547.6 | H14: CTL/PBI -> SAT/PSG -> SAT/MJI1 -> CTL/PBI
A15: 5 | B15: CTL/PBI | D15: 1762 | E15: 2 | F15: 32 | G15: 2064.6 | H15: CTL/PBI -> SAT/FKDMC -> SAT/FKNLP -> CTL/PBI
A16: 5 | B16: SAT/FKDMC | C16: 2872 | D16: 2992 | E16: 2 | F16: 32 | G16: 2064.6 | H16: CTL/PBI -> SAT/FKDMC -> SAT/FKNLP -> CTL/PBI
A17: 5 | B17: SAT/FKNLP | C17: 3240 | D17: 3360 | E17: 2 | F17: 32 | G17: 2064.6 | H17: CTL/PBI -> SAT/FKDMC -> SAT/FKNLP -> CTL/PBI
A18: 5 | B18: CTL/PBI | C18: 4232 | E18: 2 | F18: 32 | G18: 2064.6 | H18: CTL/PBI -> SAT/FKDMC -> SAT/FKNLP -> CTL/PBI
A19: 6 | B19: CTL/PBI | D19: 2444 | E19: 2 | F19: 24 | G19: 1546.6 | H19: CTL/PBI -> SAT/FKNHL -> CTL/PBI
A20: 6 | B20: SAT/FKNHL | C20: 3240 | D20: 3360 | E20: 2 | F20: 24 | G20: 1546.6 | H20: CTL/PBI -> SAT/FKNHL -> CTL/PBI
A21: 6 | B21: CTL/PBI | C21: 4156 | E21: 2 | F21: 24 | G21: 1546.6 | H21: CTL/PBI -> SAT/FKNHL -> CTL/PBI
A22: 7 | B22: CTL/PBI | D22: 3142 | E22: 2 | F22: 24 | G22: 1487.4 | H22: CTL/PBI -> SAT/FKNGAN -> CTL/PBI
A23: 7 | B23: SAT/FKNGAN | C23: 3240 | D23: 3360 | E23: 2 | F23: 24 | G23: 1487.4 | H23: CTL/PBI -> SAT/FKNGAN -> CTL/PBI
A24: 7 | B24: CTL/PBI | C24: 3458 | E24: 2 | F24: 24 | G24: 1487.4 | H24: CTL/PBI -> SAT/FKNGAN -> CTL/PBI
A25: 8 | B25: CTL/PBI | D25: 2730 | E25: 2 | F25: 32 | G25: 1857.4 | H25: CTL/PBI -> SAT/FKTEZ -> CTL/PBI
A26: 8 | B26: SAT/FKTEZ | C26: 3240 | D26: 3360 | E26: 2 | F26: 32 | G26: 1857.4 | H26: CTL/PBI -> SAT/FKTEZ -> CTL/PBI
A27: 8 | B27: CTL/PBI | C27: 3870 | E27: 2 | F27: 32 | G27: 1857.4 | H27: CTL/PBI -> SAT/FKTEZ -> CTL/PBI
A28: 9 | B28: CTL/PBI | D28: 1826 | E28: 2 | F28: 32 | G28: 2131.2 | H28: CTL/PBI -> SAT/DIG -> SAT/FKTSK -> CTL/PBI
A29: 9 | B29: SAT/DIG | C29: 3060 | D29: 3180 | E29: 2 | F29: 32 | G29: 2131.2 | H29: CTL/PBI -> SAT/DIG -> SAT/FKTSK -> CTL/PBI
A30: 9 | B30: SAT/FKTSK | C30: 3240 | D30: 3360 | E30: 2 | F30: 32 | G30: 2131.2 | H30: CTL/PBI -> SAT/DIG -> SAT/FKTSK -> CTL/PBI
A31: 9 | B31: CTL/PBI | C31: 4632 | E31: 2 | F31: 32 | G31: 2131.2 | H31: CTL/PBI -> SAT/DIG -> SAT/FKTSK -> CTL/PBI
A32: 10 | B32: CTL/PBI | D32: 2066 | E32: 2 | F32: 20 | G32: 1080.4 | H32: CTL/PBI -> SAT/DIBRUGARH -> CTL/PBI
A33: 10 | B33: SAT/DIBRUGARH | C33: 3240 | D33: 3360 | E33: 2 | F33: 20 | G33: 1080.4 | H33: CTL/PBI -> SAT/DIBRUGARH -> CTL/PBI
A34: 10 | B34: CTL/PBI | C34: 4534 | E34: 2 | F34: 20 | G34: 1080.4 | H34: CTL/PBI -> SAT/DIBRUGARH -> CTL/PBI
A35: 11 | B35: CTL/PBI | D35: 1506 | E35: 1 | F35: 20 | G35: 1213.6 | H35: CTL/PBI -> SAT/MNT1 -> SAT/RJH2 -> SAT/FKSRN -> CTL/PBI
A36: 11 | B36: SAT/MNT1 | C36: 2598 | D36: 2718 | E36: 1 | F36: 20 | G36: 1213.6 | H36: CTL/PBI -> SAT/MNT1 -> SAT/RJH2 -> SAT/FKSRN -> CTL/PBI
A37: 11 | B37: SAT/RJH2 | C37: 2858 | D37: 2978 | E37: 1 | F37: 20 | G37: 1213.6 | H37: CTL/PBI -> SAT/MNT1 -> SAT/RJH2 -> SAT/FKSRN -> CTL/PBI
A38: 11 | B38: SAT/FKSRN | C38: 3240 | D38: 3360 | E38: 1 | F38: 20 | G38: 1213.6 | H38: CTL/PBI -> SAT/MNT1 -> SAT/RJH2 -> SAT/FKSRN -> CTL/PBI
A39: 11 | B39: CTL/PBI | C39: 4338 | E39: 1 | F39: 20 | G39: 1213.6 | H39: CTL/PBI -> SAT/MNT1 -> SAT/RJH2 -> SAT/FKSRN -> CTL/PBI
A40: 12 | B40: CTL/PBI | D40: 2432 | E40: 2 | F40: 32 | G40: 2146 | H40: CTL/PBI -> SAT/FKJOR -> CTL/PBI
...

Sheet Sheet20
A1: 1 | B1: SATELLITEHUB_FKSIL | C1: SAT/FKSIL | D1: 24.8317 | E1: 92.7746 | G1: =VLOOKUP(C1,Location_file!A:A,1,0) -> SAT/FKSIL
A2: 1 | B2: SATELLITEHUB_HKD | C2: SAT/HKD | D2: 24.7184 | E2: 92.5736 | G2: =VLOOKUP(C2,Location_file!A:A,1,0) -> SAT/HKD
A3: 2 | B3: SATELLITEHUB_FKKXJ | C3: SAT/FKKXJ | D3: 0 | E3: 0 | G3: =VLOOKUP(C3,Location_file!A:A,1,0) -> SAT/FKKXJ
A4: 2 | B4: SATELLITEHUB_BDPR1 | C4: SAT/BDPR1 | D4: 0 | E4: 0 | G4: =VLOOKUP(C4,Location_file!A:A,1,0) -> SAT/BDPR1
A5: 3 | B5: SATELLITEHUB_FKSRN | C5: SAT/FKSRN | D5: 27.0219 | E5: 94.667 | G5: =VLOOKUP(C5,Location_file!A:A,1,0) -> SAT/FKSRN
A6: 3 | B6: SATELLITEHUB_MNT1 | C6: SAT/MNT1 | D6: 0 | E6: 0 | G6: =VLOOKUP(C6,Location_file!A:A,1,0) -> SAT/MNT1
A7: 3 | B7: SATELLITEHUB_RJH2 | C7: SAT/RJH2 | D7: 0 | E7: 0 | G7: =VLOOKUP(C7,Location_file!A:A,1,0) -> SAT/RJH2
A8: 4 | B8: SATELLITEHUB_BKK1 | C8: SAT/BKK1 | D8: 26.4862 | E8: 93.9782 | G8: =VLOOKUP(C8,Location_file!A:A,1,0) -> SAT/BKK1
A9: 4 | B9: SATELLITEHUB_SRU | C9: SAT/SRU | D9: 26.2833 | E9: 93.8843 | G9: =VLOOKUP(C9,Location_file!A:A,1,0) -> SAT/SRU
A10: 5 | B10: SATELLITEHUB_IMPAL | C10: SAT/IMPAL | D10: 24.747 | E10: 93.9337 | G10: =VLOOKUP(C10,Location_file!A:A,1,0) -> SAT/IMPAL
A11: 6 | B11: Satellitehub_FKNHL | C11: SAT/FKNHL | D11: 0 | E11: 0 | G11: =VLOOKUP(C11,Location_file!A:A,1,0) -> SAT/FKNHL
A12: 7 | B12: SATELLITEHUB_FKNLP | C12: SAT/FKNLP | D12: 27.2211 | E12: 94.0786 | G12: =VLOOKUP(C12,Location_file!A:A,1,0) -> SAT/FKNLP
... A52: 36 | B52: Satellitehub_PalashBari | C52: SAT/PALASHBARI | D52: 26.11 | E52: 91.53 | G52: =VLOOKUP(C52,Location_file!A:A,1,0) -> SAT/PALASHBARI

Sheet Final_Assignment
A1: route_sequence | B1: hubs | C1: dist | D1: group | E1: monthly_cost | F1: Freq | G1: total_demand | H1: assigned_vehicle_length | I1: Route_ID | J1: arrival_times | K1: departure_times | L1: updated_depot_departure | P1: 17 | Q1: 21
A2: CTL/PBI -> SAT/FKSIL -> SAT/HKD -> CTL/PBI | B2: ['SAT/FKSIL', 'SAT/HKD'] | C2: 699.1 | D2: 1.0-0 | E2: 629190 | F2: 1 | G2: 1118 | H2: 20 | I2: 24 | J2: 2988.0:3240.0:4462.0 | K2: 3108.0:3360.0 | L2: 1860 | M2: =IFERROR(__xludf.DUMMYFUNCTION("SPLIT(D2,""."",,)"),1.0) -> 1 | N2: =IFERROR(__xludf.DUMMYFUNCTION("""COMPUTED_VALUE"""),"0-0") -> 0-0 | P2: 20 | Q2: 23.72
A3: CTL/PBI -> SAT/BDPR1 -> SAT/FKKXJ -> CTL/PBI | B3: ['SAT/BDPR1', 'SAT/FKKXJ'] | C3: 681.7 | D3: 2.0-0 | E3: 393681.75 | F3: 2 | G3: 1466 | H3: 24 | I3: 25 | J3: 3014.0:3240.0:4488.0 | K3: 3134.0:3360.0 | L3: 1964 | M3: =IFERROR(__xludf.DUMMYFUNCTION("SPLIT(D3,""."",,)"),2.0) -> 2 | N3: =IFERROR(__xludf.DUMMYFUNCTION("""COMPUTED_VALUE"""),"0-0") -> 0-0 | P3: 22 | Q3: 24.4
A4: CTL/PBI -> SAT/MNT1 -> SAT/RJH2 -> SAT/FKSRN -> CTL/PBI | B4: ['SAT/MNT1', 'SAT/RJH2', 'SAT/FKSRN'] | C4: 958.6 | D4: 3.0-0 | E4: 862740 | F4: 1 | G4: 1213.6 | H4: 20 | I4: 11 | J4: 2598.0:2858.0:3240.0:4338.0 | K4: 2718.0:2978.0:3360.0 | L4: 1506 | M4: =IFERROR(__xludf.DUMMYFUNCTION("SPLIT(D4,""."",,)"),3.0) -> 3 | N4: =IFERROR(__xludf.DUMMYFUNCTION("""COMPUTED_VALUE"""),"0-0") -> 0-0 | P4: 24 | Q4: 25.23
A5: CTL/PBI -> SAT/BKK1 -> SAT/SRU -> CTL/PBI | B5: ['SAT/BKK1', 'SAT/SRU'] | C5: 666.3 | D5: 4.0-0 | E5: 384788.25 | F5: 2 | G5: 1398.6 | H5: 24 | I5: 13 | J5: 3014.0:3240.0:4146.0 | K5: 3134.0:3360.0 | L5: 2224 | M5: =IFERROR(__xludf.DUMMYFUNCTION("SPLIT(D5,""."",,)"),4.0) -> 4 | N5: =IFERROR(__xludf.DUMMYFUNCTION("""COMPUTED_VALUE"""),"0-0") -> 0-0 | P5: 14 | Q5: 19
A6: CTL/PBI -> SAT/IMPAL -> CTL/PBI | B6: ['SAT/IMPAL'] | C6: 1012 | D6: 5.0-0 | E6: 500940 | F6: 2 | G6: 969.4 | H6: 20 | I6: 22 | J6: 3240.0:4830.0 | K6: 3360 | L6: 1770 | M6: =IFERROR(__xludf.DUMMYFUNCTION("SPLIT(D6,""."",,)"),5.0) -> 5 | N6: =IFERROR(__xludf.DUMMYFUNCTION("""COMPUTED_VALUE"""),"0-0") -> 0-0
A7: CTL/PBI -> SAT/FKNHL -> CTL/PBI | B7: ['SAT/FKNHL'] | C7: 700 | D7: 6.0-0 | E7: 404250 | F7: 2 | G7: 1546.6 | H7: 24 | I7: 6 | J7: 3240.0:4156.0 | K7: 3360 | L7: 2444 | M7: =IFERROR(__xludf.DUMMYFUNCTION("SPLIT(D7,""."",,)"),6.0) -> 6 | N7: =IFERROR(__xludf.DUMMYFUNCTION("""COMPUTED_VALUE"""),"0-0") -> 0-0
A8: CTL/PBI -> SAT/FKDMC -> SAT/FKNLP -> CTL/PBI | B8: ['SAT/FKDMC', 'SAT/FKNLP'] | C8: 925.7 | D8: 7.0-0 | E8: 763702.5 | F8: 2 | G8: 2064.6 | H8: 32 | I8: 5 | J8: 2872.0:3240.0:4232.0 | K8: 2992.0:3360.0 | L8: 1762 | M8: =IFERROR(__xludf.DUMMYFUNCTION("SPLIT(D8,""."",,)"),7.0) -> 7 | N8: =IFERROR(__xludf.DUMMYFUNCTION("""COMPUTED_VALUE"""),"0-0") -> 0-0
A9: CTL/PBI -> SAT/HLF -> CTL/PBI | B9: ['SAT/HLF'] | C9: 672 | D9: 8.0-0 | E9: 277200 | F9: 2 | G9: 260 | H9: 10 | I9: 21 | J9: 3240.0:4194.0 | K9: 3360 | L9: 2406 | M9: =IFERROR(__xludf.DUMMYFUNCTION("SPLIT(D9,""."",,)"),8.0) -> 8 | N9: =IFERROR(__xludf.DUMMYFUNCTION("""COMPUTED_VALUE"""),"0-0") -> 0-0
A10: CTL/PBI -> SAT/FKSHL -> CTL/PBI | B10: ['SAT/FKSHL'] | C10: 242 | D10: 9.0-0 | E10: 199650 | F10: 2 | G10: 1672 | H10: 32 | I10: 26 | J10: 3240.0:3714.0 | K10: 3360 | L10: 2886 | M10: =IFERROR(__xludf.DUMMYFUNCTION("SPLIT(D10,""."",,)"),9.0) -> 9 | N10: =IFERROR(__xludf.DUMMYFUNCTION("""COMPUTED_VALUE"""),"0-0") -> 0-0
A11: CTL/PBI -> SAT/FKCOB -> SAT/COB1 -> CTL/PBI | B11: ['SAT/FKCOB', 'SAT/COB1'] | C11: 671.2 | D11: 10.0-0 | E11: 704760 | F11: 1 | G11: 1345 | H11: 24 | I11: 35 | J11: 3106.0:3240.0:4234.0 | K11: 3226.0:3360.0 | L11: 2240 | M11: =IFERROR(__xludf.DUMMYFUNCTION("SPLIT(D11,""."",,)"),10.0) -> 10 | N11: =IFERROR(__xludf.DUMMYFUNCTION("""COMPUTED_VALUE"""),"0-0") -> 0-0
A12: CTL/PBI -> SAT/DMP -> SAT/KMA -> CTL/PBI | B12: ['SAT/DMP', 'SAT/KMA'] | C12: 724.4 | D12: 15.0-0 | E12: 597630 | F12: 2 | G12: 1598.4 | H12: 32 | I12: 18 | J12: 2850.0:3240.0:4288.0 | K12: 2970.0:3360.0 | L12: 2174 | M12: =IFERROR(__xludf.DUMMYFUNCTION("SPLIT(D12,""."",,)"),15.0) -> 15 | N12: =IFERROR(__xludf.DUMMYFUNCTION("""COMPUTED_VALUE"""),"0-0") -> 0-0
A13: CTL/PBI -> SAT/FKHJI -> SAT/DPU -> CTL/PBI | B13: ['SAT/FKHJI', 'SAT/DPU'] | C13: 542.5 | D13: 16.0-0 | E13: 313293.75 | F13: 2 | G13: 1480 | H13: 24 | I13: 19 | J13: 2910.0:3240.0:4014.0 | K13: 3030.0:3360.0 | L13: 2442 | M13: =IFERROR(__xludf.DUMMYFUNCTION("SPLIT(D13,""."",,)"),16.0) -> 16 | N13: =IFERROR(__xludf.DUMMYFUNCTION("""COMPUTED_VALUE"""),"0-0") -> 0-0
A14: CTL/PBI -> SAT/DBI1 -> SAT/HBL1 -> CTL/PBI | B14: ['SAT/DBI1', 'SAT/HBL1'] | C14: 524.7 | D14: 17.0-0 | E14: 303014.25 | F14: 2 | G14: 1458 | H14: 24 | I14: 34 | J14: 2920.0:3240.0:3940.0 | K14: 3040.0:3360.0 | L14: 2186 | M14: =IFERROR(__xludf.DUMMYFUNCTION("SPLIT(D14,""."",,)"),17.0) -> 17 | N14: =IFERROR(__xludf.DUMMYFUNCTION("""COMPUTED_VALUE"""),"0-0") -> 0-0
A15: CTL/PBI -> SAT/BOKO -> CTL/PBI | B15: ['SAT/BOKO'] | C15: 69 | D15: 18.0-0 | E15: 34155 | F15: 2 | G15: 718 | H15: 17 | I15: 31 | J15: 3240.0:3502.0 | K15: 3360 | L15: 3098 | M15: =IFERROR(__xludf.DUMMYFUNCTION("SPLIT(D15,""."",,)"),18.0) -> 18 | N15: =IFERROR(__xludf.DUMMYFUNCTION("""COMPUTED_VALUE"""),"0-0") -> 0-0
A16: CTL/PBI -> SAT/BOKO -> SAT/FKGLPT -> CTL/PBI | B16: ['SAT/FKGLPT'] | C16: 232 | D16: 18.0-0 | E16: 114840 | F16: 2 | G16: 902 | H16: 20 | I16: 32 | J16: 3240.0:3782.0 | K16: 3360 | L16: 2818 | M16: =IFERROR(__xludf.DUMMYFUNCTION("SPLIT(D16,""."",,)"),18.0) -> 18 | N16: =IFERROR(__xludf.DUMMYFUNCTION("""COMPUTED_VALUE"""),"0-0") -> 0-0
A17: CTL/PBI -> SAT/NLV1 -> SAT/FKNLV -> CTL/PBI | B17: ['SAT/NLV1', 'SAT/FKNLV'] | C17: 202 | D17: 19.0-0 | E17: 166650 | F17: 2 | G17: 2050.2 | H17: 32 | I17: 38 | J17: 3118.0:3240.0:3634.0 | K17: 3238.0:3360.0 | L17: 2844 | M17: =IFERROR(__xludf.DUMMYFUNCTION("SPLIT(D17,""."",,)"),19.0) -> 19 | N17: =IFERROR(__xludf.DUMMYFUNCTION("""COMPUTED_VALUE"""),"0-0") -> 0-0
A18: CTL/PBI -> SAT/FKMAN -> SAT/UGR -> CTL/PBI | B18: ['SAT/FKMAN'] | C18: 141.8 | D18: 20.0-0 | E18: 70191 | F18: 2 | G18: 1154.4 | H18: 20 | I18: 1 | J18: 3240.0:3580.0 | K18: 3360 | L18: 3020 | M18: =IFERROR(__xludf.DUMMYFUNCTION("SPLIT(D18,""."",,)"),20.0) -> 20 | N18: =IFERROR(__xludf.DUMMYFUNCTION("""COMPUTED_VALUE"""),"0-0") -> 0-0
A19: CTL/PBI -> SAT/FKMAN -> SAT/UGR -> CTL/PBI | B19: ['SAT/UGR'] | C19: 222 | D19: 20.0-0 | E19: 91575 | F19: 2 | G19: 577.2 | H19: 14 | I19: 2 | J19: 3240.0:3716.0 | K19: 3360 | L19: 2884 | M19: =IFERROR(__xludf.DUMMYFUNCTION("SPLIT(D19,""."",,)"),20.0) -> 20 | N19: =IFERROR(__xludf.DUMMYFUNCTION("""COMPUTED_VALUE"""),"0-0") -> 0-0
A20: CTL/PBI -> SAT/AJL -> CTL/PBI | B20: ['SAT/AJL'] | C20: 1042 | D20: 21.0-0 | E20: 515790 | F20: 2 | G20: 1132 | H20: 20 | I20: 27 | J20: 3240.0:5162.0 | K20: 3360 | L20: 1438 | M20: =IFERROR(__xludf.DUMMYFUNCTION("SPLIT(D20,""."",,)"),21.0) -> 21 | N20: =IFERROR(__xludf.DUMMYFUNCTION("""COMPUTED_VALUE"""),"0-0") -> 0-0
A21: CTL/PBI -> SAT/FKIXA -> CTL/PBI | B21: ['SAT/FKIXA'] | C21: 1120 | D21: 22.0-0 | E21: 1680000 | F21: 1 | G21: 1554 | H21: 32 | I21: 30 | J21: 3240.0:5156.0 | K21: 3360 | L21: 1444 | M21: =IFERROR(__xludf.DUMMYFUNCTION("SPLIT(D21,""."",,)"),22.0) -> 22 | N21: =IFERROR(__xludf.DUMMYFUNCTION("""COMPUTED_VALUE"""),"0-0") -> 0-0
A22: CTL/PBI -> SAT/FKJOR -> CTL/PBI | B22: ['SAT/FKJOR'] | C22: 666 | D22: 23.0-0 | E22: 549450 | F22: 2 | G22: 2146 | H22: 32 | I22: 12 | J22: 3240.0:4168.0 | K22: 3360 | L22: 2432 | M22: =IFERROR(__xludf.DUMMYFUNCTION("SPLIT(D22,""."",,)"),23.0) -> 23 | N22: =IFERROR(__xludf.DUMMYFUNCTION("""COMPUTED_VALUE"""),"0-0") -> 0-0
A23: CTL/PBI -> SAT/PSG -> SAT/MJI1 -> CTL/PBI | B23: ['SAT/PSG', 'SAT/MJI1'] | C23: 1154 | D23: 24.0-0 | E23: 476025 | F23: 2 | G23: 547.6 | H23: 14 | I23: 4 | J23: 2558.0:3240.0:4344.0 | K23: 2678.0:3360.0 | L23: 1180 | M23: =IFERROR(__xludf.DUMMYFUNCTION("SPLIT(D23,""."",,)"),24.0) -> 24 | N23: =IFERROR(__xludf.DUMMYFUNCTION("""COMPUTED_VALUE"""),"0-0") -> 0-0
A24: CTL/PBI -> SAT/FKPSG -> SAT/UDAIPUR -> SAT/TLM -> CTL/PBI | B24: ['SAT/UDAIPUR', 'SAT/TLM'] | C24: 1181.1 | D24: 25.0-0 | E24: 584644.5 | F24: 2 | G24: 1222 | H24: 20 | I24: 28 | J24: 2910.0:3240.0:5082.0 | K24: 3030.0:3360.0 | L24: 1140 | M24: =IFERROR(__xludf.DUMMYFUNCTION("SPLIT(D24,""."",,)"),25.0) -> 25 | N24: =IFERROR(__xludf.DUMMYFUNCTION("""COMPUTED_VALUE"""),"0-0") -> 0-0
A25: CTL/PBI -> SAT/FKPSG -> CTL/PBI | B25: ['SAT/FKPSG'] | C25: 810 | D25: 25.0-0 | E25: 467775 | F25: 2 | G25: 1266 | H25: 22 | I25: 29 | J25: 3240.0:4688.0 | K25: 3360 | L25: 1912 | M25: =IFERROR(__xludf.DUMMYFUNCTION("SPLIT(D25,""."",,)"),25.0) -> 25 | N25: =IFERROR(__xludf.DUMMYFUNCTION("""COMPUTED_VALUE"""),"0-0") -> 0-0
A26: CTL/PBI -> SAT/DIBRUGARH -> SAT/DIG -> SAT/FKTSK -> CTL/PBI | B26: ['SAT/DIG', 'SAT/FKTSK'] | C26: 1043 | D26: 26.0-0 | E26: 860475 | F26: 2 | G26: 2131.2 | H26: 32 | I26: 9 | J26: 3060.0:3240.0:4632.0 | K26: 3180.0:3360.0 | L26: 1826 | M26: =IFERROR(__xludf.DUMMYFUNCTION("SPLIT(D26,""."",,)"),26.0) -> 26 | N26: =IFERROR(__xludf.DUMMYFUNCTION("""COMPUTED_VALUE"""),"0-0") -> 0-0
A27: CTL/PBI -> SAT/DIBRUGARH -> CTL/PBI | B27: ['SAT/DIBRUGARH'] | C27: 940 | D27: 26.0-0 | E27: 465300 | F27: 2 | G27: 1080.4 | H27: 20 | I27: 10 | J27: 3240.0:4534.0 | K27: 3360 | L27: 2066 | M27: =IFERROR(__xludf.DUMMYFUNCTION("SPLIT(D27,""."",,)"),26.0) -> 26 | N27: =IFERROR(__xludf.DUMMYFUNCTION("""COMPUTED_VALUE"""),"0-0") -> 0-0
A28: CTL/PBI -> SAT/JNH -> CTL/PBI | B28: ['SAT/JNH'] | C28: 364 | D28: 27.0-0 | E28: 150150 | F28: 2 | G28: 488 | H28: 14 | I28: 23 | J28: 3240.0:3852.0 | K28: 3360 | L28: 2748 | M28: =IFERROR(__xludf.DUMMYFUNCTION("SPLIT(D28,""."",,)"),27.0) -> 27 | N28: =IFERROR(__xludf.DUMMYFUNCTION("""COMPUTED_VALUE"""),"0-0") -> 0-0
A29: CTL/PBI -> SAT/MGN -> CTL/PBI | B29: ['SAT/MGN'] | C29: 100.6 | D29: 28.0-0 | E29: 49797 | F29: 2 | G29: 777 | H29: 17 | I29: 20 | J29: 3240.0:3526.0 | K29: 3360 | L29: 3074 | M29: =IFERROR(__xludf.DUMMYFUNCTION("SPLIT(D29,""."",,)"),28.0) -> 28 | N29: =IFERROR(__xludf.DUMMYFUNCTION("""COMPUTED_VALUE"""),"0-0") -> 0-0
A30: CTL/PBI -> SAT/FKNGAN -> SAT/FKTEZ -> CTL/PBI | B30: ['SAT/FKNGAN'] | C30: 51.8 | D30: 29.0-0 | E30: 29914.5 | F30: 2 | G30: 1487.4 | H30: 24 | I30: 7 | J30: 3240.0:3458.0 | K30: 3360 | L30: 3142 | M30: =IFERROR(__xludf.DUMMYFUNCTION("SPLIT(D30,""."",,)"),29.0) -> 29 | N30: =IFERROR(__xludf.DUMMYFUNCTION("""COMPUTED_VALUE"""),"0-0") -> 0-0
A31: CTL/PBI -> SAT/FKTEZ -> CTL/PBI | B31: ['SAT/FKTEZ'] | C31: 432 | D31: 29.0-0 | E31: 356400 | F31: 2 | G31: 1857.4 | H31: 32 | I31: 8 | J31: 3240.0:3870.0 | K31: 3360 | L31: 2730 | M31: =IFERROR(__xludf.DUMMYFUNCTION("SPLIT(D31,""."",,)"),29.0) -> 29 | N31: =IFERROR(__xludf.DUMMYFUNCTION("""COMPUTED_VALUE"""),"0-0") -> 0-0
A32: CTL/PBI -> SAT/FKBPRD -> SAT/FKBON -> CTL/PBI | B32: ['SAT/FKBON'] | C32: 386 | D32: 30.0-0 | E32: 191070 | F32: 2 | G32: 1148 | H32: 20 | I32: 36 | J32: 3240.0:3866.0 | K32: 3360 | L32: 2734 | M32: =IFERROR(__xludf.DUMMYFUNCTION("SPLIT(D32,""."",,)"),30.0) -> 30 | N32: =IFERROR(__xludf.DUMMYFUNCTION("""COMPUTED_VALUE"""),"0-0") -> 0-0
A33: CTL/PBI -> SAT/FKBPRD -> CTL/PBI | B33: ['SAT/FKBPRD'] | C33: 212 | D33: 30.0-0 | E33: 104940 | F33: 2 | G33: 896 | H33: 20 | I33: 37 | J33: 3240.0:3726.0 | K33: 3360 | L33: 2874 | M33: =IFERROR(__xludf.DUMMYFUNCTION("SPLIT(D33,""."",,)"),30.0) -> 30 | N33: =IFERROR(__xludf.DUMMYFUNCTION("""COMPUTED_VALUE"""),"0-0") -> 0-0
A34: CTL/PBI -> SAT/HSG -> CTL/PBI | B34: ['SAT/HSG'] | C34: 420 | D34: 31.0-0 | E34: 173250 | F34: 2 | G34: 408 | H34: 14 | I34: 33 | J34: 3240.0:4100.0 | K34: 3360 | L34: 2500 | M34: =IFERROR(__xludf.DUMMYFUNCTION("SPLIT(D34,""."",,)"),31.0) -> 31 | N34: =IFERROR(__xludf.DUMMYFUNCTION("""COMPUTED_VALUE"""),"0-0") -> 0-0
A35: CTL/PBI -> SAT/MOKO -> CTL/PBI | B35: ['SAT/MOKO'] | C35: 924 | D35: 32.0-0 | E35: 304920 | F35: 2 | G35: 125.8 | H35: 7 | I35: 15 | J35: 3240.0:4560.0 | K35: 3360 | L35: 2040 | M35: =IFERROR(__xludf.DUMMYFUNCTION("SPLIT(D35,""."",,)"),32.0) -> 32 | N35: =IFERROR(__xludf.DUMMYFUNCTION("""COMPUTED_VALUE"""),"0-0") -> 0-0
A36: CTL/PBI -> SAT/GUW -> CTL/PBI | B36: ['SAT/GUW'] | C36: 46.3 | D36: 33.0-0 | E36: 22918.5 | F36: 2 | G36: 1080.4 | H36: 20 | I36: 17 | J36: 3240.0:3450.0 | K36: 3360 | L36: 3150 | M36: =IFERROR(__xludf.DUMMYFUNCTION("SPLIT(D36,""."",,)"),33.0) -> 33 | N36: =IFERROR(__xludf.DUMMYFUNCTION("""COMPUTED_VALUE"""),"0-0") -> 0-0
A37: CTL/PBI -> SAT/Hatigaon -> CTL/PBI | B37: ['SAT/Hatigaon'] | C37: 79.6 | D37: 34.0-0 | E37: 39402 | F37: 2 | G37: 1080.4 | H37: 20 | I37: 14 | J37: 3240.0:3480.0 | K37: 3360 | L37: 3120 | M37: =IFERROR(__xludf.DUMMYFUNCTION("SPLIT(D37,""."",,)"),34.0) -> 34 | N37: =IFERROR(__xludf.DUMMYFUNCTION("""COMPUTED_VALUE"""),"0-0") -> 0-0
A38: CTL/PBI -> SAT/GUW2 -> CTL/PBI | B38: ['SAT/GUW2'] | C38: 74 | D38: 35.0-0 | E38: 36630 | F38: 2 | G38: 1080.4 | H38: 20 | I38: 16 | J38: 3240.0:3465.0 | K38: 3360 | L38: 3135 | M38: =IFERROR(__xludf.DUMMYFUNCTION("SPLIT(D38,""."",,)"),35.0) -> 35 | N38: =IFERROR(__xludf.DUMMYFUNCTION("""COMPUTED_VALUE"""),"0-0") -> 0-0
A39: CTL/PBI -> SAT/PALASHBARI -> CTL/PBI | B39: ['SAT/PALASHBARI'] | C39: 4 | D39: 36.0-0 | E39: 1980 | F39: 2 | G39: 1080.4 | H39: 20 | I39: 3 | J39: 3240.0:3375.0 | K39: 3360 | L39: 3225 | M39: =IFERROR(__xludf.DUMMYFUNCTION("SPLIT(D39,""."",,)"),36.0) -> 36 | N39: =IFERROR(__xludf.DUMMYFUNCTION("""COMPUTED_VALUE"""),"0-0") -> 0-0

Sheet Test
A1: destination | B1: city
A2: SATELLITEHUB_FKIXA | B2: Agartala | C2: 2
A3: SATELLITEHUB_GUW | B3: Guwahati
A4: Satellitehub_Hatigaon | B4: Guwahati
A5: SATELLITEHUB_FKJOR | B5: Jorhat
A6: SATELLITEHUB_FKTEZ | B6: Tezpur
A7: SATELLITEHUB_FKSIL | B7: Silchar | C7: 2
A8: SatelliteHub_FKSHL | B8: Shillong | C8: 2
A9: Satellitehub_FKNHL | B9: Naharlagun
A10: SATELLITEHUB_GUW2 | B10: Guwahati
A11: CENTRALHUB_LM_IXA3X | B11: MH-MH
A12: SATELLITEHUB_FKNGAN | B12: Nagaon
A13: SATELLITEHUB_COB1 | B13: Cooch Behar | C13: 1
A14: SATELLITEHUB_FKTSK | B14: Tinsukia
A15: SATELLITEHUB_DMP | B15: Dimapur
A16: SATELLITEHUB_FKSRN | B16: Sibsagar
A17: SATELLITEHUB_FKPSG | B17: Panisagar | C17: 2
A18: SATELLITEHUB_FKCOB | B18: Cooch Behar | C18: 1
A19: SATELLITEHUB_FKNLP | B19: Lakhimpur
A20: SATELLITEHUB_FKBON | B20: Bongaigaon | C20: 1
A21: SATELLITEHUB_AJL | B21: Aizawl
A22: SATELLITEHUB_FKMAN | B22: Managaldoi
A23: Satellitehub_Dibrugarh | B23: Dibrugarh
A24: SATELLITEHUB_BKK1 | B24: Bokakhat
A25: SATELLITEHUB_FKNLV | B25: Barbhag
A26: SATELLITEHUB_NLV1 | B26: Nalbari | C26: 1
A27: SATELLITEHUB_IMPAL | B27: Imphal
A28: SATELLITEHUB_FKHJI | B28: Hojai
A29: SATELLITEHUB_HBL1 | B29: Habrubil | C29: 1
A30: SATELLITEHUB_FKGLPT | B30: Goalpara | C30: 1
A31: SATELLITEHUB_FKKXJ | B31: Karimganj | C31: 2
A32: SATELLITEHUB_FKBPRD | B32: Barpeta | C32: 1
A33: SATELLITEHUB_FKDMC | B33: Dhemaji
A34: SATELLITEHUB_DIG | B34: Digboi
A35: SATELLITEHUB_MGN | B35: Morigaon
A36: Satellitehub_PalashBari | B36: Palashbari
A37: Satellitehub_BOKO | B37: Boko | C37: 1
A38: SATELLITEHUB_RJH2 | B38: Rajgarh
A39: Satellitehub_Udaipur | B39: Udaipur
A40: SATELLITEHUB_TLM | B40: Taliamura | C40: 2
...

Sheet Check
A1: final_group | B1: hop_count | C1: route_sequence | D1: total_demand | E1: assigned_vehicle_length | F1: arrival_times | G1: departure_times | H1: distance_savings | I1: max_distance | J1: route_distance | K1: assigned | L1: updated_depot_departure
A2: 840.0-0-0-5 hrs | B2: 2 | C2: CENTRALHUB_L_YKBX1 -> SATELLITEHUB_RUDRAPUR -> SATELLITEHUB_HLW1 -> CENTRALHUB_L_YKBX1 | D2: 1308 | E2: 22 | F2: 1515.0:1800.0:2640.0 | G2: 1695.0:1980.0 | H2: 690 | I2: 372 | J2: 760 | K2: Yes | L2: 900
A3: 840.0-0-0-5 hrs | B3: 2 | C3: CENTRALHUB_L_YKBX1 -> SATELLITEHUB_BAREILLY -> SATELLITEHUB_BUDAUN1 -> CENTRALHUB_L_YKBX1 | D3: 1270 | E3: 22 | F3: 1500.0:1800.0:2610.0 | G3: 1680.0:1980.0 | H3: 599.8 | I3: 360 | J3: 690.2 | K3: Yes | L3: 855
A4: 840.0-0-0-5 hrs | B4: 2 | C4: CENTRALHUB_L_YKBX1 -> SATELLITEHUB_DDN -> SATELLITEHUB_DDNHOPE -> CENTRALHUB_L_YKBX1 | D4: 1551 | E4: 24 | F4: 1560.0:1800.0:2595.0 | G4: 1740.0:1980.0 | H4: 564 | I4: 294 | J4: 588 | K4: Yes | L4: 975
A5: 840.0-0-0-5 hrs | B5: 2 | C5: CENTRALHUB_L_YKBX1 -> SATELLITEHUB_SIKAR -> SATELLITEHUB_JHUNJHUNU -> CENTRALHUB_L_YKBX1 | D5: 767 | E5: 17 | F5: 1515.0:1800.0:2505.0 | G5: 1695.0:1980.0 | H5: 430.6 | I5: 249 | J5: 533.4 | K5: Yes | L5: 990
A6: 840.0-0-0-5 hrs | B6: 2 | C6: CENTRALHUB_L_YKBX1 -> SATELLITEHUB_HWRF1 -> SATELLITEHUB_SHAMLI -> CENTRALHUB_L_YKBX1 | D6: 1261 | E6: 22 | F6: 1410.0:1800.0:2205.0 | G6: 1590.0:1920.0 | H6: 305 | I6: 262 | J6: 523 | K6: Yes | L6: 930
A7: 840.0-0-0-5 hrs | B7: 2 | C7: CENTRALHUB_L_YKBX1 -> SATELLITEHUB_KNL1 -> SATELLITEHUB_PANIPAT -> CENTRALHUB_L_YKBX1 | D7: 1798 | E7: 32 | F7: 1485.0:1800.0:2220.0 | G7: 1665.0:1980.0 | H7: 260.8 | I7: 202 | J7: 405.2 | K7: Yes | L7: 1140
A8: 840.0-0-0-5 hrs | B8: 2 | C8: CENTRALHUB_L_YKBX1 -> SATELLITEHUB_BULANDSHAHAR -> SATELLITEHUB_ALGR -> CENTRALHUB_L_YKBX1 | D8: 1256 | E8: 22 | F8: 1455.0:1800.0:2295.0 | G8: 1635.0:1980.0 | H8: 245 | I8: 172 | J8: 395 | K8: Yes | L8: 1140
A9: 840.0-0-0-5 hrs | B9: 1 | C9: CENTRALHUB_L_YKBX1 -> SATELLITEHUB_FTH -> CENTRALHUB_L_YKBX1 | D9: 1158 | E9: 20 | F9: 1800.0:2355.0 | G9: 1980 | H9: 0 | I9: 212 | J9: 424 | K9: Yes | L9: 1425
A10: 840.0-0-0-5 hrs | B10: 1 | C10: CENTRALHUB_L_YKBX1 -> SATELLITEHUB_SAHARANPUR -> CENTRALHUB_L_YKBX1 | D10: 1607 | E10: 24 | F10: 1800.0:2415.0 | G10: 1980 | H10: 0 | I10: 220 | J10: 440 | K10: Yes | L10: 1365
A11: 840.0-0-0-5 hrs | B11: 1 | C11: CENTRALHUB_L_YKBX1 -> SATELLITEHUB_BIJNOR -> CENTRALHUB_L_YKBX1 | D11: 489 | E11: 10 | F11: 1800.0:2460.0 | G11: 1980 | H11: 0 | I11: 228 | J11: 456 | K11: Yes | L11: 1320
A12: 840.0-0-0-5 hrs | B12: 1 | C12: CENTRALHUB_L_YKBX1 -> SATELLITEHUB_MRD -> CENTRALHUB_L_YKBX1 | D12: 1233 | E12: 22 | F12: 1800.0:2430.0 | G12: 1980 | H12: 0 | I12: 264 | J12: 528 | K12: Yes | L12: 1350

Sheet Accruals
A1: Formulated Date | B1: Facility Name_Zonal | C1: Actual Date (DD/MM/YY) | D1: BCP connection Date ( DD/MM/YY) | E1: INBOUND OR OUTBOUND | F1: Trip ID | G1: Return Trips-(1-2-3) | H1: Vendor Name | I1: Vehicle No. | J1: REGULAR/ADHOC | K1: Billed Vehicle Type (A/R) | L1: Actual VEHICLE SIZE | M1: Billing Size | N1: Fuel Type | O1: DUTY HOURS | P1: C/MENT ID | Q1: C/MENT DATE & TIME | R1: ACTUAL DATE & TIME OF ARRIVAL OR DEPARTURE | S1: BAGS | T1: ERP WEIGHT / SENDER WEIGHT | U1: Shipmen count | V1: Docket Wgt / Physical weight | W1: If the weight in N/A what wgt to be taken | X1: Local/ zonal / National | Y1: DIRECT OR VIA | Z1: SURFACE/ AIR | AA1: FTL OR COLOADING | AB1: 1WAY/2WAY | AC1: SOURCE | AD1: DESTINATION | AE1: Main Route Lane | AF1: ROUTE / LANE | AG1: OPENING KM ( Zonal) | AH1: CLOSING KM ( Zonal) | AI1: Total KM | AJ1: Rate Per Km | AK1: Amount | AL1: Toll Amount Per Trip & Green Tax | AM1: Accrual kM | AN1: Cost Per Shipment | AO1: MH - MH/DH/PH | AP1: Remarks for 0 km / absent / week off/ removal of vehicle etc. | AQ1: GATE PASS/ DOCKET NO. | AR1: Adhoc reason( why adhoc vehicle organized ) vehicle break down / salvage/ spillover / beach etc | AS1: Cross Charge % | AT1: Cross charge Amount | AU1: cross charge to -CL/B2B/MYNTRA/MH | AV1: Pcikup Location | AW1: Tagging | AX1: LH | AY1: Grocery | AZ1: NL | BA1: FM | BB1: a | BF1: ROUTE / LANE | BG1: Ok/Not Ok | BH1: Count | BI1: Cost
A2: 45809 | B2: Centralhub_L_YKBX1 | C2: 45809 | D2: 45809 | E2: Outbound | F2: FLZRP00109135258 | H2: HARI CARGO | I2: UP32PN6581 | J2: Regular | K2: Regular | L2: 22 | M2: 22 | N2: CNG | O2: 24 | P2: 241074209, 241104214, 241062891 | Q2: ######## | R2: ######## | S2: 259 | T2: 2849 | U2: 259 | V2: 2849 | W2: 2849 | X2: Zonal | Y2: Direct | Z2: Surface | AA2: FTL | AB2: 2 Way | AC2: Centralhub_L_YKBX1 | AD2: SAT/DDN-SAT/DDNH | AE2: CTL/YKBX1-SAT/DDN-CLT/DDN1-SAT/DDNH-CTL/DEL8 | AF2: CTL/YKBX1-SAT/DDN-CLT/DDN1-SAT/DDNH-CTL/DEL8 | AG2: Fixed | AH2: Fixed | AI2: 735 | AJ2: 21.5 | AK2: 15802.5 | AN2: 21.5 | AO2: MH-DH | AW2: LH | AX2: 15802.5 | BC2: ok | BF2: .CTL/YKBX1-SAT/ALGR-CTL/ALGR-CTL/DEL8 | BG2: ok | BH2: 19 | BI2: 160550
A3: 45809 | B3: Centralhub_L_YKBX1 | C3: 45809 | D3: 45809 | E3: Outbound | F3: FLZRP00109133705 | H3: Haryana Express | I3: HR55AL1283 | J3: Regular | K3: Regular | L3: 22 | M3: 22 | N3: CNG | O3: 24 | P3: 241063397, 241081073 | Q3: ######## | R3: ######## | S3: 201 | T3: 2211 | U3: 201 | V3: 2211 | W3: 2211 | X3: Zonal | Y3: Direct | Z3: Surface | AA3: FTL | AB3: 2 Way | AC3: Centralhub_L_YKBX1 | AD3: SAT/JHUN-SAT/SIKAR | AE3: CTL/YKBX1-SAT/JHUN-SAT/SIKAR-CTL/SIKA-CTL/YKBX1 | AF3: CTL/YKBX1-SAT/JHUN-SAT/SIKAR-CTL/SIKA-CTL/YKBX1 | AG3: Fixed | AH3: Fixed | AI3: 650 | AJ3: 21.5 | AK3: 13975 | AN3: 21.5 | AO3: MH-DH | AW3: LH | AX3: 13975 | BC3: ok | BF3: CTL/FRN-CTL/YKBX1-SAT/MZN-CTL/MZN-SAT/SHAM-CTL/YKBX1-CTL/FRN | BG3: ok | BH3: 1 | BI3: 8400
A4: 45809 | B4: Centralhub_L_YKBX1 | C4: 45809 | D4: 45809 | E4: Outbound | F4: FLZRP00109135385 | H4: Haryana Express | I4: HR55AU8177 | J4: Regular | K4: Regular | L4: 22 | M4: 22 | N4: CNG | O4: 24 | P4: 241064642, 241096526 | Q4: ######## | R4: ######## | S4: 221 | T4: 2431 | U4: 221 | V4: 2431 | W4: 2431 | X4: Zonal | Y4: Direct | Z4: Surface | AA4: FTL | AB4: 2 Way | AC4: Centralhub_L_YKBX1 | AD4: SAT/HWRF1 | AE4: CTL/YKBX1-SAT/HWRF1-CTL/HWRF1-CTL/DEL8 | AF4: CTL/YKBX1-SAT/HWRF1-CTL/HWRF1-CTL/DEL8 | AG4: Fixed | AH4: Fixed | AI4: 655 | AJ4: 21.5 | AK4: 14082.5 | AN4: 21.5 | AO4: MH-DH | AW4: LH | AX4: 14082.5 | BC4: ok | BF4: CTL/YKBX1-CTL/FRN-SAT/AGR1-CTL/AGR1-CTL/DEL8 | BG4: ok | BH4: 24 | BI4: 309600
A5: 45809 | B5: Centralhub_L_YKBX1 | C5: 45809 | D5: 45809 | E5: Outbound | F5: FLZRP00109135897 | H5: HARI CARGO | I5: UP32PN6580 | J5: Adhoc | K5: Adhoc | L5: 22 | M5: 22 | N5: CNG | O5: 24 | P5: 241096352, 241124751,241105801 | Q5: ######## | R5: ######## | S5: 140 | T5: 1540 | U5: 140 | V5: 1540 | W5: 1540 | X5: Zonal | Y5: Direct | Z5: Surface | AA5: FTL | AB5: 2 Way | AC5: Centralhub_L_YKBX1 | AD5: SAT/HWRF1/DDN | AE5: CTL/YKBX1-SAT/HWRF1-CTL/HWRF1-SAT/DDN-CTL/DEL8 | AF5: CTL/YKBX1-SAT/HWRF1-CTL/HWRF1-SAT/DDN-CTL/DEL8 | AG5: Fixed | AH5: Fixed | AI5: 760 | AJ5: 23.5 | AK5: 17860 | AN5: 23.5 | AO5: MH-DH | AW5: LH | AX5: 17860 | BC5: ok | BF5: CTL/YKBX1-CTL/FRN-SAT/ALWA-CTL/ALWA-CTL/DEL8 | BG5: ok | BH5: 23 | BI5: 211916.3
A6: 45809 | B6: Centralhub_L_YKBX1 | C6: 45809 | D6: 45809 | E6: Outbound | F6: FLZRP00109136194 | H6: M M LOGISTICS | I6: DL01MB0183 | J6: Regular | K6: Regular | L6: 28 | M6: 28 | N6: CNG | O6: 24 | P6: 241062726, 241072264, 241115044 | Q6: ######## | R6: ######## | S6: 663 | T6: 7293 | U6: 663 | V6: 7293 | W6: 7293 | X6: Zonal | Y6: Direct | Z6: Surface | AA6: FTL | AB6: 2 Way | AC6: Centralhub_L_YKBX1 | AD6: SAT/SAHA | AE6: CTL/YKBX1-SAT/SAHA-CTL/SAHA-CTL/DEL8 | AF6: CTL/YKBX1-SAT/SAHA-CTL/SAHA-CTL/DEL8 | AG6: Fixed | AH6: Fixed | AI6: 570 | AJ6: 23.5 | AK6: 13395 | AN6: 23.5 | AO6: MH-DH | AW6: LH | AX6: 13395 | BC6: ok
A7: 45809 | B7: Centralhub_L_YKBX1 | C7: 45809 | D7: 45809 | E7: Outbound | F7: FLZRP00109135562 | H7: RAHUL CARGO | I7: HR47E2902 | J7: Regular | K7: Regular | L7: 22 | M7: 22 | N7: CNG | O7: 24 | P7: 241062868, 241134607 | Q7: ######## | R7: ######## | S7: 207 | T7: 2277 | U7: 207 | V7: 2277 | W7: 2277 | X7: Zonal | Y7: Direct | Z7: Surface | AA7: FTL | AB7: 2 Way | AC7: Centralhub_L_YKBX1 | AD7: SAT/ALGR | AE7: .CTL/YKBX1-SAT/ALGR-CTL/ALGR-CTL/DEL8 | AF7: .CTL/YKBX1-SAT/ALGR-CTL/ALGR-CTL/DEL8 | AG7: Fixed | AH7: Fixed | AI7: 380 | AJ7: 21.5 | AK7: 8170 | AN7: 21.5 | AO7: MH-DH | AW7: LH | AX7: 8170 | BC7: ok | BF7: CTL/YKBX1-SAT/ALGR-CTL/ALGR-CTL/DEL8 | BG7: ok | BH7: 6 | BI7: 49020
A8: 45809 | B8: Centralhub_L_YKBX1 | C8: 45809 | D8: 45809 | E8: Outbound | F8: FLZRP00109136979 | H8: Chirag Road Line | I8: HR38AC7298 | J8: Regular | K8: Regular | L8: 22 | M8: 22 | N8: CNG | O8: 24 | P8: 241064831, 241141628 | Q8: ######## | R8: ######## | S8: 162 | T8: 1782 | U8: 162 | V8: 1782 | W8: 1782 | X8: Zonal | Y8: Direct | Z8: Surface | AA8: FTL | AB8: 2 Way | AC8: Centralhub_L_YKBX1 | AD8: SAT/RUDRAPUR | AE8: CTL/YKBX1-SAT/RUDRAPUR-CTL/RUDRAPUR-CTL/DEL8 | AF8: CTL/YKBX1-SAT/RUDRAPUR-CTL/DEL8 | AG8: Fixed | AH8: Fixed | AI8: 790 | AJ8: 21.5 | AK8: 16985 | AN8: 21.5 | AO8: MH-DH | AS8: 0.5 | AT8: 8492.5 | AU8: CL | AV8: CentralHub_RUDRAPUR | AW8: FM Pickup | AX8: 8492.5 | BA8: 8492.5 | BC8: ok | BF8: CTL/YKBX1-SAT/ALGR-CTL/ALGR-SAT/BUDAUN1-CTL/DEL8 | BG8: ok | BH8: 4 | BI8: 73320
A9: 45809 | B9: Centralhub_L_YKBX1 | C9: 45809 | D9: 45809 | E9: Outbound | F9: FLZRP00109137145 | H9: Chirag Road Line | I9: DL01MA7241 | J9: Regular | K9: Regular | L9: 22 | M9: 22 | N9: CNG | O9: 24 | P9: 241100007, 241110740 | Q9: ######## | R9: ######## | S9: 178 | T9: 1958 | U9: 178 | V9: 1958 | W9: 1958 | X9: Zonal | Y9: Direct | Z9: Surface | AA9: FTL | AB9: 2 Way | AC9: Centralhub_L_YKBX1 | AD9: SAT/HLW1 | AE9: CTL/YKBX1-SAT/HLW1-CTL/HLW1-CTL/YKBX1 | AF9: CTL/YKBX1-SAT/HLW1-CTL/HLW1-CTL/YKBX1 | AG9: Fixed | AH9: Fixed | AI9: 815 | AJ9: 21.5 | AK9: 17522.5 | AN9: 21.5 | AO9: MH-DH | AW9: FM Pickup | AX9: 17522.5 | BC9: ok | BF9: CTL/YKBX1-SAT/ALGR-SAT/BUDAUN1 | BG9: ok | BH9: 1 | BI9: 18330
A10: 45809 | B10: Centralhub_L_YKBX1 | C10: 45809 | D10: 45809 | E10: Outbound | F10: FLZRP00109140686 | H10: NARENDRA TRANSPORT | I10: DL01MB4009 | J10: Regular | K10: Regular | L10: 22 | M10: 22 | N10: CNG | O10: 24 | P10: 241116639, 241117962, 241134561 | Q10: ######## | R10: ######## | S10: 140 | T10: 1540 | U10: 140 | V10: 1540 | W10: 1540 | X10: Zonal | Y10: Direct | Z10: Surface | AA10: FTL | AB10: 2 Way | AC10: Centralhub_L_YKBX1 | AD10: SAT/AGR1 | AE10: CTL/YKBX1-CTL/FRN-SAT/AGR1-CTL/AGR1-CTL/DEL8 | AF10: CTL/YKBX1-CTL/FRN-SAT/AGR1-CTL/AGR1-CTL/DEL8 | AG10: Fixed | AH10: Fixed | AI10: 600 | AJ10: 21.5 | AK10: 12900 | AN10: 21.5 | AO10: MH-DH | AW10: FM Pickup | AX10: 12900 | BC10: ok | BF10: CTL/YKBX1-SAT/BARE-CTL/BAREIL-CTL/DEL8 | BG10: ok | BH10: 22 | BI10: 380000
A11: 45809 | B11: Centralhub_L_YKBX1 | C11: 45809 | D11: 45809 | E11: Outbound | F11: FLZRA00109182326 | H11: M M LOGISTICS | I11: DL01MA7110 | J11: Regular | K11: Regular | L11: 22 | M11: 22 | N11: CNG | O11: 24 | P11: 241135491, 241165401 | Q11: ######## | R11: ######## | S11: 48 | T11: 528 | U11: 48 | V11: 528 | W11: 528 | X11: Zonal | Y11: Direct | Z11: Surface | AA11: FTL | AB11: 2 Way | AC11: Centralhub_L_YKBX1 | AD11: SAT/FTH | AE11: CTL/YKBX1-SAT/FTH-CTL/FTH-CTL/DEL8 | AF11: CTL/YKBX1-SAT/FTH-CTL/FTH-CTL/DEL8 | AG11: Fixed | AH11: Fixed | AI11: 510 | AJ11: 21.5 | AK11: 10965 | AN11: 21.5 | AO11: MH-DH | AW11: FM Pickup | AX11: 10965 | BC11: ok | BF11: CTL/YKBX1-SAT/BIJNOR-CTL/BIJNOR-CTL/YKBX1 | BG11: ok | BH11: 14 | BI11: 153510
A12: 45809 | B12: Centralhub_L_YKBX1 | C12: 45809 | D12: 45809 | E12: Outbound | F12: FLZRA00109141014 | H12: M M LOGISTICS | I12: DL01M8917 | J12: Adhoc | K12: Adhoc | L12: 22 | M12: 22 | N12: CNG | O12: 24 | P12: 241099141, 241133908 | Q12: ######## | R12: ######## | S12: 205 | T12: 2255 | U12: 205 | V12: 2255 | W12: 2255 | X12: Zonal | Y12: Direct | Z12: Surface | AA12: FTL | AB12: 2 Way | AC12: Centralhub_L_YKBX1 | AD12: SAT/FTH | AE12: CTL/YKBX1-SAT/FTH | AF12: CTL/YKBX1-SAT/FTH | AG12: Fixed | AH12: Fixed | AI12: 510 | AJ12: 23.5 | AK12: 11985 | AN12: 23.5 | AO12: MH-DH | AW12: FM Pickup | AX12: 11985 | BC12: ok | BF12: CTL/YKBX1-SAT/BIJNOR-CTL/YKBX1 | BG12: ok | BH12: 1 | BI12: 10965
A13: 45809 | B13: Centralhub_L_YKBX1 | C13: 45809 | D13: 45809 | E13: Outbound | F13: FLZRP00109179150 | H13: NITIN TRANSPORT COMPANY | I13: HR55AH3720 | J13: Regular | K13: Regular | L13: 32 | M13: 32 | N13: Diesel | O13: 24 | P13: 241000000 | Q13: ######## | R13: ######## | S13: 148 | T13: 1628 | U13: 148 | V13: 1628 | W13: 1628 | X13: Zonal | Y13: Direct | Z13: Surface | AA13: FTL | AB13: 2 Way | AC13: Centralhub_L_YKBX1 | AD13: SAT/ALWA | AE13: CTL/YKBX1-CTL/FRN-SAT/ALWA-CTL/ALWA-CTL/DEL8 | AF13: CTL/YKBX1-CTL/FRN-SAT/ALWA-CTL/ALWA-CTL/DEL8 | AG13: Fixed | AH13: Fixed | AI13: 325 | AJ13: 28.4 | AK13: 9213.75 | AN13: 28.35 | AO13: MH-DH | AW13: FM Pickup | AX13: 9213.75 | BC13: ok
A14: 45809 | B14: Centralhub_L_YKBX1 | C14: 45809 | D14: 45809 | E14: Outbound | F14: FLZRP00109152084 | H14: NARENDRA TRANSPORT | I14: DL01MB4199 | J14: Regular | K14: Regular | L14: 22 | M14: 22 | N14: CNG | O14: 24 | P14: 241000000 | Q14: ######## | R14: ######## | S14: 195 | T14: 2145 | U14: 195 | V14: 2145 | W14: 2145 | X14: Zonal | Y14: Direct | Z14: Surface | AA14: FTL | AB14: 2 Way | AC14: Centralhub_L_YKBX1 | AD14: SAT/BULAND | AE14: CTL/YKBX1-SAT/BULAND-CTL/DEL8 | AF14: CTL/YKBX1-SAT/BULAND | AG14: Fixed | AH14: Fixed | AI14: 440 | AJ14: 21.5 | AK14: 9460 | AN14: 21.5 | AO14: MH-DH | AW14: FM Pickup | AX14: 9460 | BC14: ok | BF14: CTL/YKBX1-SAT/BUDAUN1 | BG14: ok | BH14: 8 | BI14: 133980
A15: 45809 | B15: Centralhub_L_YKBX1 | C15: 45809 | D15: 45809 | E15: Outbound | F15: FLZRP00109152202 | H15: RAHUL CARGO | I15: HR47E2800 | J15: Regular | K15: Regular | L15: 22 | M15: 22 | N15: CNG | O15: 24 | P15: 241130819, 241174207,241140526 | Q15: ######## | R15: ######## | S15: 231 | T15: 2541 | U15: 231 | V15: 2541 | W15: 2541 | X15: Zonal | Y15: Direct | Z15: Surface | AA15: FTL | AB15: 2 Way | AC15: Centralhub_L_YKBX1 | AD15: SAT/MZN-SAT/SHAM | AE15: CTL/YKBX1-SAT/MZN-CTL/MZN-SAT/SHAM-CTL/YKBX1 | AF15: CTL/YKBX1-SAT/MZN-CTL/MZN-SAT/SHAM-CTL/YKBX1 | AG15: Fixed | AH15: Fixed | AI15: 440 | AJ15: 21.5 | AK15: 9460 | AN15: 21.5 | AO15: MH-DH | AW15: FM Pickup | AX15: 9460 | BC15: ok | BF15: CTL/YKBX1-SAT/BUDAUN1-CTL/DEL8 | BG15: ok | BH15: 3 | BI15: 49665
A16: 45809 | B16: Centralhub_L_YKBX1 | C16: 45809 | D16: 45809 | E16: Outbound | F16: FLZRP00109152411 | H16: NARENDRA TRANSPORT | I16: DL01MB1978 | J16: Regular | K16: Regular | L16: 22 | M16: 22 | N16: CNG | O16: 24 | P16: 241161691, 241194860 | Q16: ######## | R16: ######## | S16: 219 | T16: 2409 | U16: 219 | V16: 2409 | W16: 2409 | X16: Zonal | Y16: Direct | Z16: Surface | AA16: FTL | AB16: 2 Way | AC16: Centralhub_L_YKBX1 | AD16: SAT/BARE | AE16: CTL/YKBX1-SAT/BARE-CTL/BAREIL-CTL/DEL8 | AF16: CTL/YKBX1-SAT/BARE-CTL/BAREIL-CTL/DEL8 | AG16: Fixed | AH16: Fixed | AI16: 800 | AJ16: 21.5 | AK16: 17200 | AN16: 21.5 | AO16: MH-DH | AW16: FM Pickup | AX16: 17200 | BC16: ok | BF16: CTL/YKBX1-SAT/BULAND | BG16: ok | BH16: 9 | BI16: 85140
A17: 45809 | B17: Centralhub_L_YKBX1 | C17: 45809 | D17: 45809 | E17: Outbound | F17: FLZRP00109179383 | H17: NITIN TRANSPORT COMPANY | I17: HR69C4288 | J17: Regular | K17: Regular | L17: 32 | M17: 32 | N17: Diesel | O17: 24 | P17: 241147900, 241198890, 241200117, 241201292 | Q17: ######## | R17: ######## | S17: 291 | T17: 3201 | U17: 291 | V17: 3201 | W17: 3201 | X17: Zonal | Y17: Direct | Z17: Surface | AA17: FTL | AB17: 2 Way | AC17: Centralhub_L_YKBX1 | AD17: SAT/PANI | AE17: CTL/YKBX1-SAT/PANI-CTL/PANIPA-MP/PANIPA-CTL/DEL8 | AF17: CTL/YKBX1-SAT/PANI-CTL/PANIPA-MP/PANIPA-CTL/DEL8 | AG17: Fixed | AH17: Fixed | AI17: 325 | AJ17: 28.4 | AK17: 9213.75 | AN17: 28.35 | AO17: MH-DH | AW17: FM Pickup | AX17: 9213.75 | BC17: ok
A18: 45809 | B18: Centralhub_L_YKBX1 | C18: 45809 | D18: 45809 | E18: Outbound | F18: FLZRP00109178142 | H18: NITIN TRANSPORT COMPANY | I18: HR55W2559 | J18: Regular | K18: Regular | L18: 32 | M18: 32 | N18: Diesel | O18: 24 | P18: 241185498, 241204246, 241207113 | Q18: ######## | R18: ######## | S18: 203 | T18: 2233 | U18: 203 | V18: 2233 | W18: 2233 | X18: Zonal | Y18: Direct | Z18: Surface | AA18: FTL | AB18: 2 Way | AC18: Centralhub_L_YKBX1 | AD18: SAT/KNL1 | AE18: CTL/YKBX1-SAT/KNL1-CTL/DEL8 | AF18: CTL/YKBX1-SAT/KNL1-CTL/DEL8 | AG18: Fixed | AH18: Fixed | AI18: 475 | AJ18: 28.35 | AK18: 13466.25 | AN18: 28.35 | AO18: MH-DH | AW18: FM Pickup | AX18: 13466.25 | BC18: ok
A19: 45809 | B19: Centralhub_L_YKBX1 | C19: 45809 | D19: 45809 | E19: Outbound | F19: FLZRP00109153680 | H19: M M LOGISTICS | I19: DL01MB0790 | J19: Regular | K19: Regular | L19: 22 | M19: 22 | N19: CNG | O19: 24 | P19: 241121111, 241210195 | Q19: ######## | R19: ######## | S19: 326 | T19: 3586 | U19: 326 | V19: 3586 | W19: 3586 | X19: Zonal | Y19: Direct | Z19: Surface | AA19: FTL | AB19: 2 Way | AC19: Centralhub_L_YKBX1 | AD19: SAT/MRD | AE19: CTL/YKBX1-SAT/MRD-CTL/MRD-CTL/DEL8 | AF19: CTL/YKBX1-SAT/MRD-CTL/MRD-CTL/DEL8 | AG19: Fixed | AH19: Fixed | AI19: 655 | AJ19: 21.5 | AK19: 14082.5 | AN19: 21.5 | AO19: MH-DH | AW19: FM Pickup | AX19: 14082.5 | BC19: ok | BF19: CTL/YKBX1-SAT/BULAND-CTL/BULANDSHAHAR-CTL/DEL8 | BG19: ok | BH19: 3 | BI19: 28380
A20: 45809 | B20: Centralhub_L_YKBX1 | C20: 45809 | D20: 45809 | E20: Outbound | F20: FLZRP00109209330 | H20: Haryana Express | I20: HR55AL6289 | J20: Regular | K20: Regular | L20: 22 | M20: 22 | N20: CNG | O20: 24 | P20: 241195998, 241233423 | Q20: ######## | R20: ######## | S20: 142 | T20: 1562 | U20: 142 | V20: 1562 | W20: 1562 | X20: Zonal | Y20: Direct | Z20: Surface | AA20: FTL | AB20: 2 Way | AC20: Centralhub_L_YKBX1 | AD20: SAT/MEER | AE20: CTL/YKBX1-SAT/MEER-CTL/DEL8 | AF20: CTL/YKBX1-SAT/MEER-CTL/DEL8 | AG20: Fixed | AH20: Fixed | AI20: 396 | AJ20: 21.5 | AK20: 8514 | AN20: 21.5 | AO20: MH-DH | AW20: FM Pickup | AX20: 8514 | BC20: ok | BF20: CTL/YKBX1-SAT/DDN-CLT/DDN1-SAT/DDNH-CTL/DDNH-CTL/DEL8 | BG20: ok | BH20: 6 | BI20: 94815
A21: 45809 | B21: Centralhub_L_YKBX1 | C21: 45809 | D21: 45809 | E21: Outbound | F21: FLZRP00109209484 | H21: Haryana Express | I21: HR55AW0740 | J21: Regular | K21: Regular | L21: 22 | M21: 22 | N21: CNG | O21: 24 | P21: 241207105, 241236277 , 241223064 | Q21: ######## | R21: ######## | S21: 166 | T21: 1826 | U21: 166 | V21: 1826 | W21: 1826 | X21: Zonal | Y21: Direct | Z21: Surface | AA21: FTL | AB21: 2 Way | AC21: Centralhub_L_YKBX1 | AD21: SAT/MNR-SAT/BIJNOR | AE21: CTL/YKBX1-SAT/MNR-SAT/BIJNOR-CTL/YKBX1 | AF21: CTL/YKBX1-SAT/MNR-SAT/BIJNOR-CTL/YKBX1 | AG21: Fixed | AH21: Fixed | AI21: 510 | AJ21: 21.5 | AK21: 10965 | AN21: 21.5 | AO21: MH-DH | AW21: FM Pickup | AX21: 10965 | BC21: ok | BF21: CTL/YKBX1-SAT/DDN-CLT/DDN1-SAT/DDNH-CTL/DEL8 | BG21: ok | BH21: 17 | BI21: 268642.5
A22: 45810 | B22: Centralhub_L_YKBX1 | C22: 45810 | D22: 45810 | E22: Outbound | F22: FLZRP00109135259 | H22: HARI CARGO | I22: UP32PN5570 | J22: Regular | K22: Regular | L22: 22 | M22: 22 | N22: CNG | O22: 24 | P22: ######## | Q22: ######## | R22: ######## | S22: ######## | T22: 3124 | U22: 284 | V22: 3124 | W22: 3124 | X22: Zonal | Y22: Direct | Z22: Surface | AA22: FTL | AB22: 2 Way | AC22: Centralhub_L_YKBX1 | AD22: SAT/DDN-SAT/DDNH | AE22: CTL/YKBX1-SAT/DDN-CLT/DDN1-SAT/DDNH-CTL/DEL8 | AF22: CTL/YKBX1-SAT/DDN-CLT/DDN1-SAT/DDNH-CTL/DEL8 | AG22: Fixed | AH22: Fixed | AI22: 735 | AJ22: 21.5 | AK22: 15802.5 | AN22: 21.5 | AO22: MH-DH | AW22: FM Pickup | AX22: 15802.5 | BC22: ok | BF22: CTL/YKBX1-SAT/FTH | BG22: ok | BH22: 18 | BI22: 210630
A23: 45810 | B23: Centralhub_L_YKBX1 | C23: 45810 | D23: 45810 | E23: Outbound | F23: FLZRP00109133706 | H23: Haryana Express | I23: HR55AL1938 | J23: Regular | K23: Regular | L23: 22 | M23: 22 | N23: CNG | O23: 24 | P23: ######## | Q23: ######## | R23: ######## | S23: ######## | T23: 2519 | U23: 229 | V23: 2519 | W23: 2519 | X23: Zonal | Y23: Direct | Z23: Surface | AA23: FTL | AB23: 2 Way | AC23: Centralhub_L_YKBX1 | AD23: SAT/JHUN-SAT/SIKAR | AE23: CTL/YKBX1-SAT/JHUN-SAT/SIKAR-CTL/SIKA-CTL/YKBX1 | AF23: CTL/YKBX1-SAT/JHUN-SAT/SIKAR-CTL/SIKA-CTL/YKBX1 | AG23: Fixed | AH23: Fixed | AI23: 650 | AJ23: 21.5 | AK23: 13975 | AN23: 21.5 | AO23: MH-DH | AW23: FM Pickup | AX23: 13975 | BC23: ok | BF23: CTL/YKBX1-SAT/FTH-CTL/FTH-CTL/DEL8 | BG23: ok | BH23: 19 | BI23: 209355
A24: 45810 | B24: Centralhub_L_YKBX1 | C24: 45810 | D24: 45810 | E24: Outbound | F24: FLZRP00109135386 | H24: Haryana Express | I24: HR55AS6970 | J24: Regular | K24: Regular | L24: 22 | M24: 22 | N24: CNG | O24: 24 | P24: 241305208, 241315297 | Q24: ######## | R24: ######## | S24: ######## | T24: 2860 | U24: 260 | V24: 2860 | W24: 2860 | X24: Zonal | Y24: Direct | Z24: Surface | AA24: FTL | AB24: 2 Way | AC24: Centralhub_L_YKBX1 | AD24: SAT/HWRF1 | AE24: CTL/YKBX1-SAT/HWRF1-CTL/HWRF1-CTL/DEL8 | AF24: CTL/YKBX1-SAT/HWRF1-CTL/HWRF1-CTL/DEL8 | AG24: Fixed | AH24: Fixed | AI24: 655 | AJ24: 21.5 | AK24: 14082.5 | AN24: 21.5 | AO24: MH-DH | AW24: FM Pickup | AX24: 14082.5 | BC24: ok | BF24: CTL/YKBX1-SAT/HLW1-CTL/HLW1-CTL/YKBX1 | BG24: ok | BH24: 23 | BI24: 403017.5
A25: 45810 | B25: Centralhub_L_YKBX1 | C25: 45810 | D25: 45810 | E25: Outbound | F25: FLZRP00109136195 | H25: M M LOGISTICS | I25: DL01MB0281 | J25: Regular | K25: Regular | L25: 28 | M25: 28 | N25: CNG | O25: 24 | P25: 241305155, 241308797, 241351318 | Q25: ######## | R25: ######## | S25: ######## | T25: 4675 | U25: 425 | V25: 4675 | W25: 4675 | X25: Zonal | Y25: Direct | Z25: Surface | AA25: FTL | AB25: 2 Way | AC25: Centralhub_L_YKBX1 | AD25: SAT/SAHA | AE25: CTL/YKBX1-SAT/SAHA-CTL/SAHA-CTL/DEL8 | AF25: CTL/YKBX1-SAT/SAHA-CTL/SAHA-CTL/DEL8 | AG25: Fixed | AH25: Fixed | AI25: 570 | AJ25: 23.5 | AK25: 13395 | AN25: 23.5 | AO25: MH-DH | AW25: FM Pickup | AX25: 13395 | BC25: ok
A26: 45810 | B26: Centralhub_L_YKBX1 | C26: 45810 | D26: 45810 | E26: Outbound | F26: FLZRP00109243372 | H26: RAHUL CARGO | I26: NL01AE5620 | J26: Regular | K26: Regular | L26: 22 | M26: 22 | N26: CNG | O26: 24 | P26: 241339711, 241381753 | Q26: ######## | R26: ######## | S26: ######## | T26: 2112 | U26: 192 | V26: 2112 | W26: 2112 | X26: Zonal | Y26: Direct | Z26: Surface | AA26: FTL | AB26: 2 Way | AC26: Centralhub_L_YKBX1 | AD26: SAT/ALGR | AE26: .CTL/YKBX1-SAT/ALGR-CTL/ALGR-CTL/DEL8 | AF26: .CTL/YKBX1-SAT/ALGR-CTL/ALGR-CTL/DEL8 | AG26: Fixed | AH26: Fixed | AI26: 380 | AJ26: 21.5 | AK26: 8170 | AN26: 21.5 | AO26: MH-DH | AW26: FM Pickup | AX26: 8170 | BC26: ok | BF26: CTL/YKBX1-SAT/HWRF1 | BG26: ok | BH26: 3 | BI26: 46177.5
A27: 45810 | B27: Centralhub_L_YKBX1 | C27: 45810 | D27: 45810 | E27: Outbound | F27: FLZRP00109228757 | H27: M M LOGISTICS | I27: DL01MA5430 | J27: Regular | K27: Regular | L27: 22 | M27: 22 | N27: CNG | O27: 24 | P27: ######## | Q27: ######## | R27: ######## | S27: ######## | T27: 2387 | U27: 217 | V27: 2387 | W27: 2387 | X27: Zonal | Y27: Direct | Z27: Surface | AA27: FTL | AB27: 2 Way | AC27: Centralhub_L_YKBX1 | AD27: SAT/BUDAUN1 | AE27: CTL/YKBX1-SAT/BUDAUN1 | AF27: CTL/YKBX1-SAT/BUDAUN1-CTL/DEL8 | AG27: Fixed | AH27: Fixed | AI27: 770 | AJ27: 21.5 | AK27: 16555 | AN27: 21.5 | AO27: MH-DH | AW27: FM Pickup | AX27: 16555 | BC27: ok | BF27: CTL/YKBX1-SAT/HWRF1-CTL/HWRF1-CTL/DEL8 | BG27: ok | BH27: 26 | BI27: 371385
A28: 45810 | B28: Centralhub_L_YKBX1 | C28: 45810 | D28: 45810 | E28: Outbound | F28: FLZRP00109136980 | H28: Chirag Road Line | I28: HR38AC0661 | J28: Regular | K28: Regular | L28: 22 | M28: 22 | N28: CNG | O28: 24 | P28: 241305145, 241337705, 241380187 | Q28: ######## | R28: ######## | S28: ######## | T28: 1914 | U28: 174 | V28: 1914 | W28: 1914 | X28: Zonal | Y28: Direct | Z28: Surface | AA28: FTL | AB28: 2 Way | AC28: Centralhub_L_YKBX1 | AD28: SAT/RUDRAPUR | AE28: CTL/YKBX1-SAT/RUDRAPUR-CTL/RUDRAPUR-CTL/DEL8 | AF28: CTL/YKBX1-SAT/RUDRAPUR-CTL/DEL8 | AG28: Fixed | AH28: Fixed | AI28: 790 | AJ28: 21.5 | AK28: 16985 | AN28: 21.5 | AO28: MH-DH | AS28: 0.5 | AT28: 8492.5 | AU28: CL | AV28: CentralHub_RUDRAPUR | AW28: FM Pickup | AX28: 8492.5 | BA28: 8492.5 | BC28: ok | BF28: CTL/YKBX1-SAT/HWRF1-CTL/HWRF1-SAT/DDN-CTL/DEL8 | BG28: ok | BH28: 7 | BI28: 125020
A29: 45810 | B29: Centralhub_L_YKBX1 | C29: 45810 | D29: 45810 | E29: Outbound | F29: FLZRP00109137146 | H29: Chirag Road Line | I29: HR38AC2491 | J29: Regular | K29: Regular | L29: 22 | M29: 22 | N29: CNG | O29: 24 | P29: ######## | Q29: ######## | R29: ######## | S29: ######## | T29: 1859 | U29: 169 | V29: 1859 | W29: 1859 | X29: Zonal | Y29: Direct | Z29: Surface | AA29: FTL | AB29: 2 Way | AC29: Centralhub_L_YKBX1 | AD29: SAT/HLW1 | AE29: CTL/YKBX1-SAT/HLW1-CTL/HLW1-CTL/YKBX1 | AF29: CTL/YKBX1-SAT/HLW1-CTL/HLW1-CTL/YKBX1 | AG29: Fixed | AH29: Fixed | AI29: 815 | AJ29: 21.5 | AK29: 17522.5 | AN29: 21.5 | AO29: MH-DH | AW29: FM Pickup | AX29: 17522.5 | BC29: ok | BF29: CTL/YKBX1-SAT/JHUN-SAT/SIKAR-CTL/SIKA-CTL/YKBX1 | BG29: ok | BH29: 23 | BI29: 321425
A30: 45810 | B30: Centralhub_L_YKBX1 | C30: 45810 | D30: 45810 | E30: Outbound | F30: FLZRP00109223328 | H30: NARENDRA TRANSPORT | I30: DL01MB1904 | J30: Regular | K30: Regular | L30: 22 | M30: 22 | N30: CNG | O30: 24 | P30: 241342408, 241344317 | Q30: ######## | R30: ######## | S30: ######## | T30: 1155 | U30: 105 | V30: 1155 | W30: 1155 | X30: Zonal | Y30: Direct | Z30: Surface | AA30: FTL | AB30: 2 Way | AC30: Centralhub_L_YKBX1 | AD30: SAT/AGR1 | AE30: CTL/YKBX1-CTL/FRN-SAT/AGR1-CTL/AGR1-CTL/DEL8 | AF30: CTL/YKBX1-CTL/FRN-SAT/AGR1-CTL/AGR1-CTL/DEL8 | AG30: Fixed | AH30: Fixed | AI30: 600 | AJ30: 21.5 | AK30: 12900 | AN30: 21.5 | AO30: MH-DH | AW30: FM Pickup | AX30: 12900 | BC30: ok | BF30: CTL/YKBX1-SAT/KNL1-CTL/DEL8 | BG30: ok | BH30: 27 | BI30: 292552.5
A31: 45810 | B31: Centralhub_L_YKBX1 | C31: 45810 | D31: 45810 | E31: Outbound | F31: FLZRP00109222031 | H31: M M LOGISTICS | I31: DL01MA7110 | J31: Regular | K31: Regular | L31: 22 | M31: 22 | N31: CNG | O31: 24 | P31: 241000000 | Q31: ######## | R31: ######## | S31: ######## | T31: 572 | U31: 52 | V31: 572 | W31: 572 | X31: Zonal | Y31: Direct | Z31: Surface | AA31: FTL | AB31: 2 Way | AC31: Centralhub_L_YKBX1 | AD31: SAT/FTH | AE31: CTL/YKBX1-SAT/FTH-CTL/FTH-CTL/DEL8 | AF31: CTL/YKBX1-SAT/FTH-CTL/FTH-CTL/DEL8 | AG31: Fixed | AH31: Fixed | AI31: 510 | AJ31: 21.5 | AK31: 10965 | AN31: 21.5 | AO31: MH-DH | AW31: FM Pickup | AX31: 10965 | BC31: ok | BF31: CTL/YKBX1-SAT/MEER-CTL/DEL8 | BG31: ok | BH31: 25 | BI31: 215226
A32: 45810 | B32: Centralhub_L_YKBX1 | C32: 45810 | D32: 45810 | E32: Outbound | F32: FLZRP00109226270 | H32: M M LOGISTICS | I32: DL01M8917 | J32: Adhoc | K32: Adhoc | L32: 22 | M32: 22 | N32: CNG | O32: 24 | P32: 241000000 | Q32: ######## | R32: ######## | S32: ######## | T32: 2288 | U32: 208 | V32: 2288 | W32: 2288 | X32: Zonal | Y32: Direct | Z32: Surface | AA32: FTL | AB32: 2 Way | AC32: Centralhub_L_YKBX1 | AD32: SAT/FTH | AE32: CTL/YKBX1-SAT/FTH | AF32: CTL/YKBX1-SAT/FTH | AG32: Fixed | AH32: Fixed | AI32: 510 | AJ32: 23.5 | AK32: 11985 | AN32: 23.5 | AO32: MH-DH | AW32: FM Pickup | AX32: 11985 | BC32: ok | BF32: CTL/YKBX1-SAT/MEER-CTL/YKBX1 | BG32: ok | BH32: 1 | BI32: 8514
A33: 45810 | B33: Centralhub_L_YKBX1 | C33: 45810 | D33: 45810 | E33: Outbound | F33: FLZRP00109223642 | H33: NITIN TRANSPORT COMPANY | I33: HR55AH3720 | J33: Regular | K33: Regular | L33: 32 | M33: 32 | N33: Diesel | O33: 24 | P33: 241000000 | Q33: ######## | R33: ######## | S33: ######## | T33: 1881 | U33: 171 | V33: 1881 | W33: 1881 | X33: Zonal | Y33: Direct | Z33: Surface | AA33: FTL | AB33: 2 Way | AC33: Centralhub_L_YKBX1 | AD33: SAT/ALWA | AE33: CTL/YKBX1-CTL/FRN-SAT/ALWA-CTL/ALWA-CTL/DEL8 | AF33: CTL/YKBX1-CTL/FRN-SAT/ALWA-CTL/ALWA-CTL/DEL8 | AG33: Fixed | AH33: Fixed | AI33: 325 | AJ33: 28.4 | AK33: 9213.75 | AN33: 28.35 | AO33: MH-DH | AW33: FM Pickup | AX33: 9213.75 | BC33: ok
A34: 45810 | B34: Centralhub_L_YKBX1 | C34: 45810 | D34: 45810 | E34: Outbound | F34: FLZRA00109208148 | H34: NARENDRA TRANSPORT | I34: DL01MB1863 | J34: Regular | K34: Regular | L34: 22 | M34: 22 | N34: CNG | O34: 24 | P34: 241363890,241343560, 241386651 | Q34: ######## | R34: ######## | S34: ######## | T34: 2420 | U34: 220 | V34: 2420 | W34: 2420 | X34: Zonal | Y34: Direct | Z34: Surface | AA34: FTL | AB34: 2 Way | AC34: Centralhub_L_YKBX1 | AD34: SAT/BARE | AE34: CTL/YKBX1-SAT/BARE-CTL/BAREIL-CTL/DEL8 | AF34: CTL/YKBX1-SAT/BARE-CTL/BAREIL-CTL/DEL8 | AG34: Fixed | AH34: Fixed | AI34: 800 | AJ34: 21.5 | AK34: 17200 | AN34: 21.5 | AO34: MH-DH | AW34: FM Pickup | AX34: 17200 | BC34: ok | BF34: CTL/YKBX1-SAT/MNR-CTL/YKBX1 | BG34: ok | BH34: 16 | BI34: 113520
A35: 45810 | B35: Centralhub_L_YKBX1 | C35: 45810 | D35: 45810 | E35: Outbound | F35: FLZRP00109251084 | H35: NARENDRA TRANSPORT | I35: DL01MA7788 | J35: Adhoc | K35: Adhoc | L35: 22 | M35: 22 | N35: CNG | O35: 24 | P35: 241000000 | Q35: ######## | R35: ######## | S35: ######## | T35: 1914 | U35: 174 | V35: 1914 | W35: 1914 | X35: Zonal | Y35: Direct | Z35: Surface | AA35: FTL | AB35: 2 Way | AC35: Centralhub_L_YKBX1 | AD35: SAT/BARE | AE35: CTL/YKBX1-SAT/BARE-CTL/BAREIL-CTL/DEL8 | AF35: CTL/YKBX1-SAT/BARE-CTL/BAREIL-CTL/DEL8 | AG35: Fixed | AH35: Fixed | AI35: 800 | AJ35: 23.5 | AK35: 18800 | AN35: 23.5 | AO35: MH-DH | AW35: FM Pickup | AX35: 18800 | BC35: ok | BF35: CTL/YKBX1-SAT/MNR--CTL/YKBX1 | BG35: ok | BH35: 1 | BI35: 10857.5
A36: 45810 | B36: Centralhub_L_YKBX1 | C36: 45810 | D36: 45810 | E36: Outbound | F36: FLZRP00109251746 | H36: NITIN TRANSPORT COMPANY | I36: HR69C4288 | J36: Regular | K36: Regular | L36: 32 | M36: 32 | N36: Diesel | O36: 24 | P36: 241384110, 24140632 | Q36: ######## | R36: ######## | S36: ######## | T36: 2684 | U36: 244 | V36: 2684 | W36: 2684 | X36: Zonal | Y36: Direct | Z36: Surface | AA36: FTL | AB36: 2 Way | AC36: Centralhub_L_YKBX1 | AD36: SAT/PANI | AE36: CTL/YKBX1-SAT/PANI-CTL/PANIPA-MP/PANIPA-CTL/DEL8 | AF36: CTL/YKBX1-SAT/PANI-CTL/PANIPA-MP/PANIPA-CTL/DEL8 | AG36: Fixed | AH36: Fixed | AI36: 325 | AJ36: 28.4 | AK36: 9213.75 | AN36: 28.35 | AO36: MH-DH | AW36: FM Pickup | AX36: 9213.75 | BC36: ok
A37: 45810 | B37: Centralhub_L_YKBX1 | C37: 45810 | D37: 45810 | E37: Outbound | F37: FLZRP00109224689 | H37: NITIN TRANSPORT COMPANY | I37: HR55W2559 | J37: Regular | K37: Regular | L37: 32 | M37: 32 | N37: Diesel | O37: 24 | P37: 241383013, 241446374 | Q37: ######## | R37: ######## | S37: ######## | T37: 2728 | U37: 248 | V37: 2728 | W37: 2728 | X37: Zonal | Y37: Direct | Z37: Surface | AA37: FTL | AB37: 2 Way | AC37: Centralhub_L_YKBX1 | AD37: SAT/KNL1 | AE37: CTL/YKBX1-SAT/KNL1-CTL/DEL8 | AF37: CTL/YKBX1-SAT/KNL1-CTL/DEL8 | AG37: Fixed | AH37: Fixed | AI37: 475 | AJ37: 28.35 | AK37: 13466.25 | AN37: 28.35 | AO37: MH-DH | AW37: FM Pickup | AX37: 13466.25 | BC37: ok
A38: 45810 | B38: Centralhub_L_YKBX1 | C38: 45810 | D38: 45810 | E38: Outbound | F38: FLZRP00109224799 | H38: M M LOGISTICS | I38: DL01LAE7323 | J38: Regular | K38: Regular | L38: 22 | M38: 22 | N38: CNG | O38: 24 | P38: 241000000 | Q38: ######## | R38: ######## | S38: ######## | T38: 2728 | U38: 248 | V38: 2728 | W38: 2728 | X38: Zonal | Y38: Direct | Z38: Surface | AA38: FTL | AB38: 2 Way | AC38: Centralhub_L_YKBX1 | AD38: SAT/MRD | AE38: CTL/YKBX1-SAT/MRD-CTL/MRD-CTL/DEL8 | AF38: CTL/YKBX1-SAT/MRD-CTL/MRD-CTL/DEL8 | AG38: Fixed | AH38: Fixed | AI38: 655 | AJ38: 21.5 | AK38: 14082.5 | AN38: 21.5 | AO38: MH-DH | AW38: FM Pickup | AX38: 14082.5 | BC38: ok | BF38: CTL/YKBX1-SAT/MNR-SAT/BIJNOR-CTL/BIJNOR-CTL/YKBX1 | BG38: ok | BH38: 2 | BI38: 21930
A39: 45810 | B39: Centralhub_L_YKBX1 | C39: 45810 | D39: 45810 | E39: Outbound | F39: FLZRP00109256280 | H39: Haryana Express | I39: HR55AL4152 | J39: Regular | K39: Regular | L39: 22 | M39: 22 | N39: CNG | O39: 24 | P39: 241422011, 241479405 | Q39: ######## | R39: ######## | S39: ######## | T39: 2046 | U39: 186 | V39: 2046 | W39: 2046 | X39: Zonal | Y39: Direct | Z39: Surface | AA39: FTL | AB39: 2 Way | AC39: Centralhub_L_YKBX1 | AD39: SAT/MEER | AE39: CTL/YKBX1-SAT/MEER-CTL/DEL8 | AF39: CTL/YKBX1-SAT/MEER-CTL/DEL8 | AG39: Fixed | AH39: Fixed | AI39: 396 | AJ39: 21.5 | AK39: 8514 | AN39: 21.5 | AO39: MH-DH | AW39: FM Pickup | AX39: 8514 | BC39: ok | BF39: CTL/YKBX1-SAT/MNR-SAT/BIJNOR-CTL/YKBX1 | BG39: ok | BH39: 5 | BI39: 54825
A40: 45810 | B40: Centralhub_L_YKBX1 | C40: 45810 | D40: 45810 | E40: Outbound | F40: FLZRP00109258534 | H40: Haryana Express | I40: HR55AJ8857 | J40: Regular | K40: Regular | L40: 22 | M40: 22 | N40: CNG | O40: 24 | P40: 241480581, 241490081 | Q40: ######## | R40: ######## | S40: ######## | T40: 682 | U40: 62 | V40: 682 | W40: 682 | X40: Zonal | Y40: Direct | Z40: Surface | AA40: FTL | AB40: 2 Way | AC40: Centralhub_L_YKBX1 | AD40: SAT/MNR | AE40: CTL/YKBX1-SAT/MNR--CTL/YKBX1 | AF40: CTL/YKBX1-SAT/MNR--CTL/YKBX1 | AG40: Fixed | AH40: Fixed | AI40: 505 | AJ40: 21.5 | AK40: 10857.5 | AN40: 21.5 | AO40: MH-DH | AW40: FM Pickup | AX40: 10857.5 | BC40: ok | BF40: CTL/YKBX1-SAT/MRD-CTL/MRD-CTL/DEL8 | BG40: ok | BH40: 26 | BI40: 370075
...

Sheet Sheet17
A1: consignment_id | B1: ref_id | C1: trip_id | D1: mode | E1: type | F1: business_entity_type | G1: trip_type | H1: trip_tag | I1: contract_type | J1: supply_chain | K1: trip_source | L1: trip_destination | M1: trip_source_type | N1: trip_dest_type | O1: source_zone | P1: dest_zone | Q1: execution_type | R1: trip_route | S1: trip_status | T1: event_trip_created_datetime | U1: event_trip_confirmed_datetime | V1: event_trip_started_datetime | W1: event_trip_completed_datetime | X1: event_trip_aborted_datetime | Y1: event_trip_cancelled_datetime | Z1: trip_end_datetime | AA1: consignment_source_id | AB1: consignment_destination_id | AC1: consignment_source_hub_type | AD1: consignment_dest_hub_type | AE1: consignment_source_client | AF1: consignment_dest_client | AG1: consignment_source | AH1: consignment_destination | AI1: consignment_created_at | AJ1: consignment_received_at | AK1: consignment_weight | AL1: consignment_status | AM1: consignment_volume | AN1: vehicle_number | AO1: vehicle_length | AP1: vehicle_breadth | AQ1: vehicle_height | AR1: vendor_id | AS1: vendor_name | AT1: mr_flag | AU1: bag_no_of_load_units | AV1: shipment_no_of_load_units | AW1: semi_large_no_of_load_units | AX1: box_no_of_load_units | AY1: large_no_of_load_units | AZ1: tote_no_of_load_units | BA1: total_fk_bag_shipments | BB1: total_shipment_shipments | BC1: total_fk_semi_large_shipments | BD1: total_box_shipments | BE1: total_large_shipments | BF1: total_gtnl_shipments | BG1: total_tote_shipments | BH1: bag_fwd_shipments | BI1: semi_large_fwd_shipments | BJ1: large_fwd_shipments | BK1: tote_fwd_shipments | BL1: bag_rev_shipments | BM1: shipment_rev_shipments | BN1: semi_large_rev_shipments | BO1: box_rev_shipments | BP1: large_rev_shipments | BQ1: gtnl_rev_shipments | BR1: tote_rev_shipments | BS1: vehicle_type_name | BT1: consignment_type | BU1: MYN_SYN_flag | BV1: NL_Synergy_flag | BW1: Trip_Tagging | BX1: consignment_source_city | BY1: consignment_dest_city | BZ1: trip_source_city | CA1: trip_dest_city | CB1: two_way_flag | CC1: abort_user | CD1: create_user | CE1: consignment_closed_time | CF1: execution_type_new | CG1: total_myn_shipments | CH1: myn_fwd_shipments | CI1: myn_rev_shipments
A2: 251000000 | B2: FLLRP00110675932 | C2: 111000000 | D2: ROAD | E2: LOCAL | F2: FSD | G2: MH - DH | H2: LH | I2: FLEET | J2: Non_Large | K2: MotherHub_JJH | L2: GandhinagarMPHub_DEL | M2: MOTHER_HUB | N2: DELIVERY_HUB | O2: North | P2: North | Q2: PLANNED | R2: GUR/JJH-DEL/GDM | S2: COMPLETED | T2: ######## | U2: ######## | V2: ######## | W2: ######## | Z2: ######## | AA2: 296232 | AB2: 192551 | AC2: MOTHER_HUB | AD2: DELIVERY_HUB | AE2: FLIPKART | AF2: FLIPKART | AG2: MotherHub_JJH | AH2: GandhinagarMPHub_DEL | AI2: ######## | AJ2: ######## | AK2: 1912.19 | AL2: DELIVERED | AM2: 0 | AN2: DL01LAJ6738 | AO2: 17 | AP2: 7 | AQ2: 7 | AR2: 753 | AS2: M/s Xpress Logistics Solution | AT2: 0 | AU2: 153 | AV2: 0 | AW2: 0 | AX2: 0 | AY2: 0 | AZ2: 0 | BA2: 4976 | BB2: 0 | BC2: 0 | BD2: 0 | BE2: 0 | BF2: 0 | BG2: 0 | BH2: 470 | BI2: 0 | BJ2: 0 | BK2: 0 | BL2: 4506 | BM2: 0 | BN2: 0 | BO2: 0 | BP2: 0 | BQ2: 0 | BR2: 0 | BS2: 17 FT | BT2: BAG | BU2: FK | BV2: 0 | BX2: JHAJJAR | BY2: DELHI | BZ2: JHAJJAR | CA2: DELHI | CB2: 0 | CD2: neeraj.chandra | CE2: ######## | CF2: Adhoc | CG2: 251 | CH2: 3 | CI2: 248
